Workbook

Sheet Read me
A1: UC15 ERP Data Platform: Source-to-target mapping
A3: Purpose | B3: Shows, for every column in the PostgreSQL data warehouse (uc15_dw), where the data comes from and what is done to it on the way.
A4: Data path | B4: Raw file in datasets/ > cleaned file in silver/cleansing/ > Pentaho transformation > warehouse table.
A5: Sheets | B5: Table summary: one row per table, in load order. Column mapping: one row per column. Relationships: the foreign keys between tables.
A6: How it was produced | B6: Generated from the table definitions (sql/01_create_star_schema.sql), the 15 Pentaho transformations in pentaho/transformations/, and the headers of the raw and cleaned files. It is not typed by hand.
A7: Row counts | B7: The Rows loaded values are the counts that sql/05_reconciliation_checks.sql confirms after each load.
A8: Scope | B8: Covers the 15 warehouse tables. The real-time REST API demo (realtime_rest_demo) and the ETL audit table (etl_run_log) are separate and are not mapped here.
A10: Checks
A11: Tables documented | B11: =COUNTA('Table summary'!B5:B19) -> 15
A12: Columns documented | B12: =COUNTA('Column mapping'!C5:C145) -> 141
A13: Columns counted per table | B13: ='Table summary'!K20 -> 141
A14: Foreign keys listed | B14: =COUNTA(Relationships!B5:B18) -> 14
A15: Counts agree? | B15: =IF(B12=B13,"Yes","CHECK") -> Yes
A17: Legend (Key / constraint)
A18: PK | B18: Primary key of the table
A19: FK to X.y | B19: Foreign key: must match column y in table X
A20: Unique | B20: No two rows can have the same value
A21: Not null | B21: The column cannot be empty

Sheet Column mapping
A1: Source-to-target mapping: every column of every warehouse table
A2: One row per target column. Read left to right: where it comes from (raw file, cleaned file), what was done to it, and how Pentaho loads it.
A4: # | B4: Target table | C4: Target column | D4: Data type | E4: Key / constraint | F4: Source dataset | G4: Raw file (datasets/) | H4: Raw column | I4: Cleaned file (silver/) | J4: Cleaned column | K4: Cleaning applied | L4: Transformation rule (Pentaho) | M4: Pentaho transformation | N4: Notes from the table definition
A5: 1 | B5: DimMonth | C5: month_key | D5: SMALLINT | E5: PK | F5: Month list (generated) | H5: (generated by python/generate_reference_data.py) | I5: silver/cleansing/reference_data/DimMonth.csv | K5: Not applicable | L5: Copied as is. | M5: Load DimMonth.ktr | N5: 1-12, no year (seasonal pattern only)
A6: 2 | B6: DimMonth | C6: month_name | D6: VARCHAR(15) | E6: Not null | F6: Month list (generated) | H6: (generated by python/generate_reference_data.py) | I6: silver/cleansing/reference_data/DimMonth.csv | K6: Not applicable | L6: Copied as is. | M6: Load DimMonth.ktr
A7: 3 | B7: DimDate | C7: date_key | D7: INT | E7: PK | F7: Calendar (generated) | H7: (generated by python/generate_reference_data.py) | I7: silver/cleansing/reference_data/DimDate.csv | K7: Not applicable | L7: Copied as is. | M7: Load DimDate.ktr | N7: format YYYYMMDD
A8: 4 | B8: DimDate | C8: full_date | D8: DATE | E8: Not null | F8: Calendar (generated) | H8: (generated by python/generate_reference_data.py) | I8: silver/cleansing/reference_data/DimDate.csv | K8: Not applicable | L8: Read as a date (yyyy-MM-dd). | M8: Load DimDate.ktr
A9: 5 | B9: DimDate | C9: year | D9: SMALLINT | E9: Not null | F9: Calendar (generated) | H9: (generated by python/generate_reference_data.py) | I9: silver/cleansing/reference_data/DimDate.csv | K9: Not applicable | L9: Copied as is. | M9: Load DimDate.ktr
A10: 6 | B10: DimDate | C10: quarter | D10: SMALLINT | E10: Not null | F10: Calendar (generated) | H10: (generated by python/generate_reference_data.py) | I10: silver/cleansing/reference_data/DimDate.csv | K10: Not applicable | L10: Copied as is. | M10: Load DimDate.ktr
A11: 7 | B11: DimDate | C11: month | D11: SMALLINT | E11: Not null | F11: Calendar (generated) | H11: (generated by python/generate_reference_data.py) | I11: silver/cleansing/reference_data/DimDate.csv | K11: Not applicable | L11: Copied as is. | M11: Load DimDate.ktr
A12: 8 | B12: DimDate | C12: month_name | D12: VARCHAR(15) | E12: Not null | F12: Calendar (generated) | H12: (generated by python/generate_reference_data.py) | I12: silver/cleansing/reference_data/DimDate.csv | K12: Not applicable | L12: Copied as is. | M12: Load DimDate.ktr
A13: 9 | B13: DimDate | C13: day | D13: SMALLINT | E13: Not null | F13: Calendar (generated) | H13: (generated by python/generate_reference_data.py) | I13: silver/cleansing/reference_data/DimDate.csv | K13: Not applicable | L13: Copied as is. | M13: Load DimDate.ktr
A14: 10 | B14: DimDate | C14: day_of_week | D14: SMALLINT | E14: Not null | F14: Calendar (generated) | H14: (generated by python/generate_reference_data.py) | I14: silver/cleansing/reference_data/DimDate.csv | K14: Not applicable | L14: Copied as is. | M14: Load DimDate.ktr | N14: 1=Monday .. 7=Sunday
A15: 11 | B15: DimDate | C15: day_name | D15: VARCHAR(15) | E15: Not null | F15: Calendar (generated) | H15: (generated by python/generate_reference_data.py) | I15: silver/cleansing/reference_data/DimDate.csv | K15: Not applicable | L15: Copied as is. | M15: Load DimDate.ktr
A16: 12 | B16: DimDate | C16: is_weekend | D16: BOOLEAN | E16: Not null | F16: Calendar (generated) | H16: (generated by python/generate_reference_data.py) | I16: silver/cleansing/reference_data/DimDate.csv | K16: Not applicable | L16: Copied as is. | M16: Load DimDate.ktr
A17: 13 | B17: DimDate | C17: week_of_year | D17: SMALLINT | E17: Not null | F17: Calendar (generated) | H17: (generated by python/generate_reference_data.py) | I17: silver/cleansing/reference_data/DimDate.csv | K17: Not applicable | L17: Copied as is. | M17: Load DimDate.ktr
A18: 14 | B18: DimEmployee | C18: employee_key | D18: SERIAL | E18: PK | F18: Employee | G18: datasets/employee_data.xls | H18: (none) | I18: silver/cleansing/cleaned_datasets/employee_data_cleaned.csv | K18: Not applicable | L18: Generated by PostgreSQL: a sequence number (surrogate key). | M18: Load DimEmployee.ktr | N18: generated: source has
A19: 15 | B19: DimEmployee | C19: first_name | D19: VARCHAR(100) | F19: Employee | G19: datasets/employee_data.xls | H19: First Name | I19: silver/cleansing/cleaned_datasets/employee_data_cleaned.csv | J19: first_name | K19: Name standardised (lower case, underscores) | L19: Copied as is. | M19: Load DimEmployee.ktr
A20: 16 | B20: DimEmployee | C20: last_name | D20: VARCHAR(100) | F20: Employee | G20: datasets/employee_data.xls | H20: Last Name | I20: silver/cleansing/cleaned_datasets/employee_data_cleaned.csv | J20: last_name | K20: Name standardised (lower case, underscores) | L20: Copied as is. | M20: Load DimEmployee.ktr
A21: 17 | B21: DimEmployee | C21: gender | D21: VARCHAR(20) | F21: Employee | G21: datasets/employee_data.xls | H21: Gender | I21: silver/cleansing/cleaned_datasets/employee_data_cleaned.csv | J21: gender | K21: Name standardised (lower case, underscores) | L21: Copied as is. | M21: Load DimEmployee.ktr
A22: 18 | B22: DimEmployee | C22: age | D22: SMALLINT | F22: Employee | G22: datasets/employee_data.xls | H22: Age | I22: silver/cleansing/cleaned_datasets/employee_data_cleaned.csv | J22: age | K22: Name standardised (lower case, underscores) | L22: Copied as is. | M22: Load DimEmployee.ktr
A23: 19 | B23: DimEmployee | C23: salary | D23: NUMERIC(12,2) | F23: Employee | G23: datasets/employee_data.xls | H23: Salary | I23: silver/cleansing/cleaned_datasets/employee_data_cleaned.csv | J23: salary | K23: Name standardised (lower case, underscores) | L23: Copied as is. | M23: Load DimEmployee.ktr
A24: 20 | B24: DimEmployee | C24: expenditure | D24: NUMERIC(12,2) | F24: Employee | G24: datasets/employee_data.xls | H24: Expenditure | I24: silver/cleansing/cleaned_datasets/employee_data_cleaned.csv | J24: expenditure | K24: Name standardised (lower case, underscores) | L24: Copied as is. | M24: Load DimEmployee.ktr
A25: 21 | B25: DimEmployee | C25: savings | D25: NUMERIC(12,2) | F25: Employee | G25: datasets/employee_data.xls | H25: Savings | I25: silver/cleansing/cleaned_datasets/employee_data_cleaned.csv | J25: savings | K25: Name standardised (lower case, underscores) | L25: Copied as is. | M25: Load DimEmployee.ktr
A26: 22 | B26: DimEmployee | C26: expenditure_percentage | D26: NUMERIC(6,4) | F26: Employee | G26: datasets/employee_data.xls | H26: Expenditure Percentage | I26: silver/cleansing/cleaned_datasets/employee_data_cleaned.csv | J26: expenditure_percentage | K26: Name standardised (lower case, underscores) | L26: Copied as is. | M26: Load DimEmployee.ktr
A27: 23 | B27: DimEmployee | C27: savings_percentage | D27: NUMERIC(6,4) | F27: Employee | G27: datasets/employee_data.xls | H27: Savings Percentage | I27: silver/cleansing/cleaned_datasets/employee_data_cleaned.csv | J27: savings_percentage | K27: Name standardised (lower case, underscores) | L27: Copied as is. | M27: Load DimEmployee.ktr
A28: 24 | B28: DimAsset | C28: asset_key | D28: SERIAL | E28: PK | F28: Asset | G28: datasets/Asset_data.xml | H28: (none) | I28: silver/cleansing/cleaned_datasets/asset_data_cleaned.csv | K28: Not applicable | L28: Generated by PostgreSQL: a sequence number (surrogate key). | M28: Load DimAsset.ktr
A29: 25 | B29: DimAsset | C29: asset_id | D29: VARCHAR(20) | E29: Unique, Not null | F29: Asset | G29: datasets/Asset_data.xml | H29: asset_id | I29: silver/cleansing/cleaned_datasets/asset_data_cleaned.csv | J29: asset_id | K29: Name unchanged | L29: Copied as is. | M29: Load DimAsset.ktr
A30: 26 | B30: DimAsset | C30: location | D30: VARCHAR(100) | F30: Asset | G30: datasets/Asset_data.xml | H30: location | I30: silver/cleansing/cleaned_datasets/asset_data_cleaned.csv | J30: location | K30: Name unchanged | L30: Copied as is. | M30: Load DimAsset.ktr
A31: 27 | B31: DimAsset | C31: install_year | D31: SMALLINT | F31: Asset | G31: datasets/Asset_data.xml | H31: install_year | I31: silver/cleansing/cleaned_datasets/asset_data_cleaned.csv | J31: install_year | K31: Name unchanged | L31: Copied as is. | M31: Load DimAsset.ktr
A32: 28 | B32: DimAsset | C32: last_maintenance_year | D32: SMALLINT | F32: Asset | G32: datasets/Asset_data.xml | H32: last_maintenance_year | I32: silver/cleansing/cleaned_datasets/asset_data_cleaned.csv | J32: last_maintenance_year | K32: Name unchanged | L32: Copied as is. | M32: Load DimAsset.ktr
A33: 29 | B33: DimAsset | C33: usage_hours_per_month | D33: NUMERIC(10,2) | F33: Asset | G33: datasets/Asset_data.xml | H33: usage_hours_per_month | I33: silver/cleansing/cleaned_datasets/asset_data_cleaned.csv | J33: usage_hours_per_month | K33: Name unchanged | L33: Copied as is. | M33: Load DimAsset.ktr
A34: 30 | B34: DimAsset | C34: failure_count | D34: SMALLINT | F34: Asset | G34: datasets/Asset_data.xml | H34: failure_count | I34: silver/cleansing/cleaned_datasets/asset_data_cleaned.csv | J34: failure_count | K34: Name unchanged | L34: Copied as is. | M34: Load DimAsset.ktr
A35: 31 | B35: DimAsset | C35: condition_score | D35: NUMERIC(6,4) | F35: Asset | G35: datasets/Asset_data.xml | H35: condition_score | I35: silver/cleansing/cleaned_datasets/asset_data_cleaned.csv | J35: condition_score | K35: Name unchanged | L35: Copied as is. | M35: Load DimAsset.ktr
A36: 32 | B36: DimAsset | C36: maintenance_cost_last_year | D36: NUMERIC(12,2) | F36: Asset | G36: datasets/Asset_data.xml | H36: maintenance_cost_last_year | I36: silver/cleansing/cleaned_datasets/asset_data_cleaned.csv | J36: maintenance_cost_last_year | K36: Name unchanged | L36: Copied as is. | M36: Load DimAsset.ktr
A37: 33 | B37: DimAsset | C37: asset_type | D37: VARCHAR(50) | F37: Asset | G37: datasets/Asset_data.xml | H37: asset_type | I37: silver/cleansing/cleaned_datasets/asset_data_cleaned.csv | J37: asset_type | K37: Name unchanged | L37: Copied as is. | M37: Load DimAsset.ktr
A38: 34 | B38: DimAsset | C38: operational_state | D38: VARCHAR(30) | F38: Asset | G38: datasets/Asset_data.xml | H38: operational_state | I38: silver/cleansing/cleaned_datasets/asset_data_cleaned.csv | J38: operational_state | K38: Name unchanged | L38: Copied as is. | M38: Load DimAsset.ktr
A39: 35 | B39: DimAsset | C39: disposal_decision | D39: VARCHAR(30) | F39: Asset | G39: datasets/Asset_data.xml | H39: disposal_decision | I39: silver/cleansing/cleaned_datasets/asset_data_cleaned.csv | J39: disposal_decision | K39: Name unchanged | L39: Copied as is. | M39: Load DimAsset.ktr
A40: 36 | B40: DimSupplier | C40: supplier_key | D40: SERIAL | E40: PK | F40: Procurement | G40: datasets/procurement_all.csv | H40: (none) | I40: silver/cleansing/cleaned_datasets/procurement_all_cleaned.csv | K40: Not applicable | L40: Generated by PostgreSQL: a sequence number (surrogate key). | M40: Load DimSupplier.ktr
A41: 37 | B41: DimSupplier | C41: supplier_id | D41: VARCHAR(20) | E41: Unique, Not null | F41: Procurement | G41: datasets/procurement_all.csv | H41: supplier_id | I41: silver/cleansing/cleaned_datasets/procurement_all_cleaned.csv | J41: supplier_id | K41: Name unchanged | L41: Each different supplier_id in the file is kept once (duplicates removed). | M41: Load DimSupplier.ktr
...

Sheet Table summary
A1: Table summary: the 15 warehouse tables in the order the Pentaho job loads them
A2: Rows loaded are the counts confirmed by sql/05_reconciliation_checks.sql. Columns is a formula that counts the rows of the Column mapping sheet.
A4: Load order | B4: Target table | C4: Type | D4: One row is | E4: Source dataset | F4: Raw file (datasets/) | G4: Cleaned file (silver/) | H4: Pentaho transformation | I4: Depends on (loaded first) | J4: Rows loaded | K4: Columns | L4: Cleaning applied in the Silver layer
A5: 1 | B5: DimMonth | C5: Dimension | D5: One month of the year (1 to 12) | E5: Month list (generated) | F5: (generated by python/generate_reference_data.py) | G5: silver/cleansing/reference_data/DimMonth.csv | H5: Load DimMonth.ktr | I5: None | J5: 12 | K5: =COUNTIF('Column mapping'!$B$5:$B$145,B5) -> 2 | L5: Calendar generated by a script; not from a source system
A6: 2 | B6: DimDate | C6: Dimension | D6: One calendar day, 2011-01-01 to 2027-12-31 | E6: Calendar (generated) | F6: (generated by python/generate_reference_data.py) | G6: silver/cleansing/reference_data/DimDate.csv | H6: Load DimDate.ktr | I6: None | J6: 6209 | K6: =COUNTIF('Column mapping'!$B$5:$B$145,B6) -> 11 | L6: Calendar generated by a script; not from a source system
A7: 3 | B7: DimEmployee | C7: Dimension | D7: One employee | E7: Employee | F7: datasets/employee_data.xls | G7: silver/cleansing/cleaned_datasets/employee_data_cleaned.csv | H7: Load DimEmployee.ktr | I7: None | J7: 35 | K7: =COUNTIF('Column mapping'!$B$5:$B$145,B7) -> 10 | L7: Names standardised; types converted; no rows removed
A8: 4 | B8: DimAsset | C8: Dimension | D8: One piece of equipment | E8: Asset | F8: datasets/Asset_data.xml | G8: silver/cleansing/cleaned_datasets/asset_data_cleaned.csv | H8: Load DimAsset.ktr | I8: None | J8: 1245 | K8: =COUNTIF('Column mapping'!$B$5:$B$145,B8) -> 12 | L8: Names standardised; types converted; no rows removed
A9: 5 | B9: DimSupplier | C9: Dimension | D9: One supplier (ID only) | E9: Procurement | F9: datasets/procurement_all.csv | G9: silver/cleansing/cleaned_datasets/procurement_all_cleaned.csv | H9: Load DimSupplier.ktr | I9: None | J9: 10 | K9: =COUNTIF('Column mapping'!$B$5:$B$145,B9) -> 2 | L9: Names standardised; types converted; no rows removed
A10: 6 | B10: DimCustomerMaster | C10: Dimension | D10: One customer | E10: Customer Master | F10: datasets/Customer_Master.json | G10: silver/cleansing/cleaned_datasets/customer_master_cleaned.csv | H10: Load DimCustomerMaster.ktr | I10: None | J10: 1500 | K10: =COUNTIF('Column mapping'!$B$5:$B$145,B10) -> 12 | L10: Names standardised; nested contact and address kept as JSON text; no rows removed
A11: 7 | B11: DimItemInventory | C11: Dimension | D11: One inventory item | E11: Inventory | F11: datasets/Inventory_data.json | G11: silver/cleansing/cleaned_datasets/inventory_data_cleaned.csv | H11: Load DimItemInventory.ktr | I11: None | J11: 1000 | K11: =COUNTIF('Column mapping'!$B$5:$B$145,B11) -> 5 | L11: Names standardised; types converted; no rows removed
A12: 8 | B12: DimWarehouseItem | C12: Dimension | D12: One warehouse item | E12: Warehouse | F12: datasets/warehouse.csv | G12: silver/cleansing/cleaned_datasets/warehouse_data_cleaned.csv | H12: Load DimWarehouseItem.ktr | I12: None | J12: 3204 | K12: =COUNTIF('Column mapping'!$B$5:$B$145,B12) -> 5 | L12: Exact duplicate rows removed (6,408 raw rows became 3,204)
A13: 9 | B13: FactSales | C13: Fact | D13: One sales transaction | E13: Sales | F13: datasets/Sales_data.csv | G13: silver/cleansing/cleaned_datasets/sales_data_cleaned.csv | H13: Load FactSales.ktr | I13: DimDate | J13: 1000 | K13: =COUNTIF('Column mapping'!$B$5:$B$145,B13) -> 11 | L13: Dates converted from DD-MM-YYYY to YYYY-MM-DD; names standardised; no rows removed
A14: 10 | B14: FactFinance | C14: Fact | D14: One finance transaction | E14: Finance | F14: datasets/Finance_data.csv | G14: silver/cleansing/cleaned_datasets/finance_data_cleaned.csv | H14: Load FactFinance.ktr | I14: DimDate | J14: 1000 | K14: =COUNTIF('Column mapping'!$B$5:$B$145,B14) -> 13 | L14: Names standardised; types converted; no rows removed
A15: 11 | B15: FactManufacturing | C15: Fact | D15: One production job | E15: Manufacturing | F15: datasets/Manufacturing_data.xml | G15: silver/cleansing/cleaned_datasets/manufacturing_data_cleaned.csv | H15: Load FactManufacturing.ktr | I15: DimDate | J15: 1000 | K15: =COUNTIF('Column mapping'!$B$5:$B$145,B15) -> 12 | L15: Names standardised; dates converted; no rows removed
A16: 12 | B16: FactAccountsReceivable | C16: Fact | D16: One receivable document | E16: Account (Accounts Receivable) | F16: datasets/Account_data.xls | G16: silver/cleansing/cleaned_datasets/account_data_cleaned.csv | H16: Load FactAccountsReceivable.ktr | I16: DimDate | J16: 45839 | K16: =COUNTIF('Column mapping'!$B$5:$B$145,B16) -> 14 | L16: Names standardised; dates converted to YYYY-MM-DD; no rows removed
... A19: 15 | B19: FactInventoryDemand | C19: Fact | D19: One inventory item in one month | E19: Inventory | F19: datasets/Inventory_data.json | G19: silver/cleansing/cleaned_datasets/inventory_data_cleaned.csv | H19: Load FactInventoryDemand.ktr | I19: DimItemInventory, DimMonth | J19: 12000 | K19: =COUNTIF('Column mapping'!$B$5:$B$145,B19) -> 3 | L19: Names standardised; types converted; no rows removed
B20: Total | J20: =SUM(J5:J19) -> 78558 | K20: =SUM(K5:K19) -> 141

Sheet Relationships
A1: Relationships: foreign keys between the warehouse tables
A2: From the table definition (sql/01_create_star_schema.sql). Each row says: this column must match a key in another table.
A4: # | B4: Fact / table | C4: Column | D4: References table | E4: References column | F4: Can be empty?
A5: 1 | B5: FactSales | C5: date_key | D5: DimDate | E5: date_key | F5: No
A6: 2 | B6: FactFinance | C6: date_key | D6: DimDate | E6: date_key | F6: No
A7: 3 | B7: FactManufacturing | C7: scheduled_start_date_key | D7: DimDate | E7: date_key | F7: No
A8: 4 | B8: FactManufacturing | C8: actual_start_date_key | D8: DimDate | E8: date_key | F8: Yes
A9: 5 | B9: FactAccountsReceivable | C9: doc_date_key | D9: DimDate | E9: date_key | F9: No
A10: 6 | B10: FactAccountsReceivable | C10: net_due_date_key | D10: DimDate | E10: date_key | F10: Yes
A11: 7 | B11: FactAccountsReceivable | C11: clearing_date_key | D11: DimDate | E11: date_key | F11: Yes
A12: 8 | B12: FactProcurement | C12: order_date_key | D12: DimDate | E12: date_key | F12: No
A13: 9 | B13: FactProcurement | C13: expected_delivery_date_key | D13: DimDate | E13: date_key | F13: Yes
A14: 10 | B14: FactProcurement | C14: supplier_key | D14: DimSupplier | E14: supplier_key | F14: No
A15: 11 | B15: FactWarehouseSnapshot | C15: date_key | D15: DimDate | E15: date_key | F15: No
A16: 12 | B16: FactWarehouseSnapshot | C16: warehouse_item_key | D16: DimWarehouseItem | E16: warehouse_item_key | F16: No
... A18: 14 | B18: FactInventoryDemand | C18: month_key | D18: DimMonth | E18: month_key | F18: No
